Hello, I am  2
Hello, I am  0
Hello, I am  1
Traceback (most recent call last):
  File "GCN_Cora_Distributed_MulNode.py", line 185, in <module>
    main(rank, world_size, host_addr_full)
  File "GCN_Cora_Distributed_MulNode.py", line 153, in main
    partitions = partition_data(dataset, world_size-1)
  File "/home/dsys2352/DSassignment/GCN/utils.py", line 197, in partition_data_louvain
    data.num_nodes = dataset.num_nodes
AttributeError: 'Planetoid' object has no attribute 'num_nodes'
Traceback (most recent call last):
  File "GCN_Cora_Distributed_MulNode.py", line 185, in <module>
    main(rank, world_size, host_addr_full)
  File "GCN_Cora_Distributed_MulNode.py", line 159, in main
    dataset = recv_object(src=0)
  File "/home/dsys2352/DSassignment/GCN/utils.py", line 285, in recv_object
    dist.recv(size, src=src)
  File "/home/dsys2352/miniconda3/envs/dist_GNN/lib/python3.6/site-packages/torch/distributed/distributed_c10d.py", line 850, in recv
    pg.recv([tensor], src, tag).wait()
RuntimeError: [/pytorch/third_party/gloo/gloo/transport/tcp/pair.cc:575] Connection closed by peer [10.141.0.1]:15798
Traceback (most recent call last):
  File "GCN_Cora_Distributed_MulNode.py", line 185, in <module>
    main(rank, world_size, host_addr_full)
  File "GCN_Cora_Distributed_MulNode.py", line 159, in main
    dataset = recv_object(src=0)
  File "/home/dsys2352/DSassignment/GCN/utils.py", line 285, in recv_object
    dist.recv(size, src=src)
  File "/home/dsys2352/miniconda3/envs/dist_GNN/lib/python3.6/site-packages/torch/distributed/distributed_c10d.py", line 850, in recv
    pg.recv([tensor], src, tag).wait()
RuntimeError: [/pytorch/third_party/gloo/gloo/transport/tcp/pair.cc:575] Connection closed by peer [10.141.0.1]:54170
Traceback (most recent call last):
  File "/home/dsys2352/miniconda3/envs/dist_GNN/lib/python3.6/runpy.py", line 193, in _run_module_as_main
    "__main__", mod_spec)
  File "/home/dsys2352/miniconda3/envs/dist_GNN/lib/python3.6/runpy.py", line 85, in _run_code
    exec(code, run_globals)
  File "/home/dsys2352/miniconda3/envs/dist_GNN/lib/python3.6/site-packages/torch/distributed/launch.py", line 340, in <module>
    main()
  File "/home/dsys2352/miniconda3/envs/dist_GNN/lib/python3.6/site-packages/torch/distributed/launch.py", line 326, in main
    sigkill_handler(signal.SIGTERM, None)  # not coming back
  File "/home/dsys2352/miniconda3/envs/dist_GNN/lib/python3.6/site-packages/torch/distributed/launch.py", line 301, in sigkill_handler
    raise subprocess.CalledProcessError(returncode=last_return_code, cmd=cmd)
subprocess.CalledProcessError: Command '['/home/dsys2352/miniconda3/envs/dist_GNN/bin/python', '-u', 'GCN_Cora_Distributed_MulNode.py']' returned non-zero exit status 1.
Killing subprocess 1096651
Traceback (most recent call last):
  File "/home/dsys2352/miniconda3/envs/dist_GNN/lib/python3.6/runpy.py", line 193, in _run_module_as_main
    "__main__", mod_spec)
  File "/home/dsys2352/miniconda3/envs/dist_GNN/lib/python3.6/runpy.py", line 85, in _run_code
    exec(code, run_globals)
  File "/home/dsys2352/miniconda3/envs/dist_GNN/lib/python3.6/site-packages/torch/distributed/launch.py", line 340, in <module>
    main()
  File "/home/dsys2352/miniconda3/envs/dist_GNN/lib/python3.6/site-packages/torch/distributed/launch.py", line 326, in main
    sigkill_handler(signal.SIGTERM, None)  # not coming back
  File "/home/dsys2352/miniconda3/envs/dist_GNN/lib/python3.6/site-packages/torch/distributed/launch.py", line 301, in sigkill_handler
    raise subprocess.CalledProcessError(returncode=last_return_code, cmd=cmd)
subprocess.CalledProcessError: Command '['/home/dsys2352/miniconda3/envs/dist_GNN/bin/python', '-u', 'GCN_Cora_Distributed_MulNode.py']' returned non-zero exit status 1.
Killing subprocess 1916994
srun: error: node002: task 1: Exited with exit code 1
srun: error: node001: task 0: Exited with exit code 1
Traceback (most recent call last):
  File "/home/dsys2352/miniconda3/envs/dist_GNN/lib/python3.6/runpy.py", line 193, in _run_module_as_main
    "__main__", mod_spec)
  File "/home/dsys2352/miniconda3/envs/dist_GNN/lib/python3.6/runpy.py", line 85, in _run_code
    exec(code, run_globals)
  File "/home/dsys2352/miniconda3/envs/dist_GNN/lib/python3.6/site-packages/torch/distributed/launch.py", line 340, in <module>
    main()
  File "/home/dsys2352/miniconda3/envs/dist_GNN/lib/python3.6/site-packages/torch/distributed/launch.py", line 326, in main
    sigkill_handler(signal.SIGTERM, None)  # not coming back
  File "/home/dsys2352/miniconda3/envs/dist_GNN/lib/python3.6/site-packages/torch/distributed/launch.py", line 301, in sigkill_handler
    raise subprocess.CalledProcessError(returncode=last_return_code, cmd=cmd)
subprocess.CalledProcessError: Command '['/home/dsys2352/miniconda3/envs/dist_GNN/bin/python', '-u', 'GCN_Cora_Distributed_MulNode.py']' returned non-zero exit status 1.
Killing subprocess 291021
srun: error: node024: task 2: Exited with exit code 1
