Hello, I am  2
Hello, I am  1
Hello, I am  0
data sent to node 1
data received on node 1 from node 0
tensor([   0,    1,    2,  ..., 1351, 1352, 1353])
data sent to node 2
data received on node 2 from node 0
tensor([[0., 0., 0.,  ..., 0., 0., 0.],
        [0., 0., 0.,  ..., 0., 0., 0.],
        [0., 0., 0.,  ..., 0., 0., 0.],
        ...,
        [0., 0., 0.,  ..., 0., 0., 0.],
        [0., 0., 0.,  ..., 0., 0., 0.],
        [0., 0., 0.,  ..., 0., 0., 0.]]) torch.Size([1354, 1433])
tensor([[   0,    0,    0,  ..., 1326, 1326, 1326],
        [ 318,  950, 1253,  ...,  302,  740, 1325]]) torch.Size([2, 5742])
world size 3
0
0
Traceback (most recent call last):
  File "GCN_Cora_Distributed_MulNode.py", line 174, in <module>
    main(rank, world_size, host_addr_full)
  File "GCN_Cora_Distributed_MulNode.py", line 160, in main
    _, pred = model(data).max(dim=1)
  File "/home/dsys2352/miniconda3/envs/dist_GNN/lib/python3.6/site-packages/torch/nn/modules/module.py", line 889, in _call_impl
tensor([1354, 1355, 1356,  ..., 2705, 2706, 2707])
    result = self.forward(*input, **kwargs)
  File "GCN_Cora_Distributed_MulNode.py", line 125, in forward
    x = self.conv1(x, edge_index)
  File "/home/dsys2352/miniconda3/envs/dist_GNN/lib/python3.6/site-packages/torch/nn/modules/module.py", line 889, in _call_impl
    result = self.forward(*input, **kwargs)
  File "GCN_Cora_Distributed_MulNode.py", line 19, in forward
    return self.propagate(edge_index, size=(x.size(0), x.size(0)), x=x)
  File "/home/dsys2352/miniconda3/envs/dist_GNN/lib/python3.6/site-packages/torch_geometric/nn/conv/message_passing.py", line 310, in propagate
    size, kwargs)
  File "/home/dsys2352/miniconda3/envs/dist_GNN/lib/python3.6/site-packages/torch_geometric/nn/conv/message_passing.py", line 202, in __collect__
    j if arg[-2:] == '_j' else i)
  File "/home/dsys2352/miniconda3/envs/dist_GNN/lib/python3.6/site-packages/torch_geometric/nn/conv/message_passing.py", line 171, in __lift__
    return src.index_select(self.node_dim, index)
IndexError: index out of range in self
tensor([[0., 0., 0.,  ..., 0., 0., 0.],
        [0., 0., 1.,  ..., 0., 0., 0.],
        [0., 0., 0.,  ..., 0., 0., 0.],
        ...,
        [0., 0., 0.,  ..., 0., 0., 0.],
        [0., 0., 0.,  ..., 0., 0., 0.],
        [0., 0., 0.,  ..., 0., 0., 0.]]) torch.Size([1354, 1433])
tensor([[   2,    2, 1354,  ..., 1329, 1328, 1327],
        [1512, 2184, 1530,  ..., 2008, 1673, 1494]]) torch.Size([2, 5688])
world size 3
97
Traceback (most recent call last):
  File "GCN_Cora_Distributed_MulNode.py", line 174, in <module>
    main(rank, world_size, host_addr_full)
  File "GCN_Cora_Distributed_MulNode.py", line 160, in main
    _, pred = model(data).max(dim=1)
  File "/home/dsys2352/miniconda3/envs/dist_GNN/lib/python3.6/site-packages/torch/nn/modules/module.py", line 889, in _call_impl
    result = self.forward(*input, **kwargs)
  File "GCN_Cora_Distributed_MulNode.py", line 105, in forward
    requested_nodes_list = recv_object(src = 1)
  File "/home/dsys2352/DSassignment/GCN/utils.py", line 284, in recv_object
    dist.recv(size, src=src)
  File "/home/dsys2352/miniconda3/envs/dist_GNN/lib/python3.6/site-packages/torch/distributed/distributed_c10d.py", line 850, in recv
    pg.recv([tensor], src, tag).wait()
RuntimeError: [/pytorch/third_party/gloo/gloo/transport/tcp/pair.cc:575] Connection closed by peer [10.141.0.2]:18858
Traceback (most recent call last):
  File "/home/dsys2352/miniconda3/envs/dist_GNN/lib/python3.6/runpy.py", line 193, in _run_module_as_main
    "__main__", mod_spec)
  File "/home/dsys2352/miniconda3/envs/dist_GNN/lib/python3.6/runpy.py", line 85, in _run_code
    exec(code, run_globals)
  File "/home/dsys2352/miniconda3/envs/dist_GNN/lib/python3.6/site-packages/torch/distributed/launch.py", line 340, in <module>
    main()
  File "/home/dsys2352/miniconda3/envs/dist_GNN/lib/python3.6/site-packages/torch/distributed/launch.py", line 326, in main
    sigkill_handler(signal.SIGTERM, None)  # not coming back
  File "/home/dsys2352/miniconda3/envs/dist_GNN/lib/python3.6/site-packages/torch/distributed/launch.py", line 301, in sigkill_handler
    raise subprocess.CalledProcessError(returncode=last_return_code, cmd=cmd)
subprocess.CalledProcessError: Command '['/home/dsys2352/miniconda3/envs/dist_GNN/bin/python', '-u', 'GCN_Cora_Distributed_MulNode.py']' returned non-zero exit status 1.
Killing subprocess 1093634
srun: error: node002: task 1: Exited with exit code 1
Killing subprocess 288209
Traceback (most recent call last):
  File "/home/dsys2352/miniconda3/envs/dist_GNN/lib/python3.6/runpy.py", line 193, in _run_module_as_main
    "__main__", mod_spec)
  File "/home/dsys2352/miniconda3/envs/dist_GNN/lib/python3.6/runpy.py", line 85, in _run_code
    exec(code, run_globals)
  File "/home/dsys2352/miniconda3/envs/dist_GNN/lib/python3.6/site-packages/torch/distributed/launch.py", line 340, in <module>
    main()
  File "/home/dsys2352/miniconda3/envs/dist_GNN/lib/python3.6/site-packages/torch/distributed/launch.py", line 326, in main
    sigkill_handler(signal.SIGTERM, None)  # not coming back
  File "/home/dsys2352/miniconda3/envs/dist_GNN/lib/python3.6/site-packages/torch/distributed/launch.py", line 301, in sigkill_handler
    raise subprocess.CalledProcessError(returncode=last_return_code, cmd=cmd)
subprocess.CalledProcessError: Command '['/home/dsys2352/miniconda3/envs/dist_GNN/bin/python', '-u', 'GCN_Cora_Distributed_MulNode.py']' returned non-zero exit status 1.
srun: error: node024: task 2: Exited with exit code 1
