Hello, I am  2
Hello, I am  1
Hello, I am  0
data sent to node 1
data received on node 1 from node 0
Traceback (most recent call last):
  File "GCN_Cora_Distributed_MulNode.py", line 178, in <module>
    main(rank, world_size, host_addr_full)
  File "GCN_Cora_Distributed_MulNode.py", line 164, in main
    _, pred = model(data).max(dim=1)
  File "/home/dsys2352/miniconda3/envs/dist_GNN/lib/python3.6/site-packages/torch/nn/modules/module.py", line 889, in _call_impl
    result = self.forward(*input, **kwargs)
  File "GCN_Cora_Distributed_MulNode.py", line 82, in forward
    requested_nodes_list = data.communication_sources(0)
TypeError: 'list' object is not callable
data sent to node 2
data received on node 2 from node 0
Traceback (most recent call last):
  File "GCN_Cora_Distributed_MulNode.py", line 178, in <module>
    main(rank, world_size, host_addr_full)
  File "GCN_Cora_Distributed_MulNode.py", line 164, in main
    _, pred = model(data).max(dim=1)
  File "/home/dsys2352/miniconda3/envs/dist_GNN/lib/python3.6/site-packages/torch/nn/modules/module.py", line 889, in _call_impl
    result = self.forward(*input, **kwargs)
  File "GCN_Cora_Distributed_MulNode.py", line 82, in forward
    requested_nodes_list = data.communication_sources(0)
TypeError: 'list' object is not callable
Traceback (most recent call last):
  File "/home/dsys2352/miniconda3/envs/dist_GNN/lib/python3.6/runpy.py", line 193, in _run_module_as_main
    "__main__", mod_spec)
  File "/home/dsys2352/miniconda3/envs/dist_GNN/lib/python3.6/runpy.py", line 85, in _run_code
    exec(code, run_globals)
  File "/home/dsys2352/miniconda3/envs/dist_GNN/lib/python3.6/site-packages/torch/distributed/launch.py", line 340, in <module>
    main()
  File "/home/dsys2352/miniconda3/envs/dist_GNN/lib/python3.6/site-packages/torch/distributed/launch.py", line 326, in main
    sigkill_handler(signal.SIGTERM, None)  # not coming back
  File "/home/dsys2352/miniconda3/envs/dist_GNN/lib/python3.6/site-packages/torch/distributed/launch.py", line 301, in sigkill_handler
    raise subprocess.CalledProcessError(returncode=last_return_code, cmd=cmd)
subprocess.CalledProcessError: Command '['/home/dsys2352/miniconda3/envs/dist_GNN/bin/python', '-u', 'GCN_Cora_Distributed_MulNode.py']' returned non-zero exit status 1.
Killing subprocess 1094754
srun: error: node002: task 1: Exited with exit code 1
Traceback (most recent call last):
  File "/home/dsys2352/miniconda3/envs/dist_GNN/lib/python3.6/runpy.py", line 193, in _run_module_as_main
    "__main__", mod_spec)
  File "/home/dsys2352/miniconda3/envs/dist_GNN/lib/python3.6/runpy.py", line 85, in _run_code
    exec(code, run_globals)
  File "/home/dsys2352/miniconda3/envs/dist_GNN/lib/python3.6/site-packages/torch/distributed/launch.py", line 340, in <module>
    main()
  File "/home/dsys2352/miniconda3/envs/dist_GNN/lib/python3.6/site-packages/torch/distributed/launch.py", line 326, in main
    sigkill_handler(signal.SIGTERM, None)  # not coming back
  File "/home/dsys2352/miniconda3/envs/dist_GNN/lib/python3.6/site-packages/torch/distributed/launch.py", line 301, in sigkill_handler
    raise subprocess.CalledProcessError(returncode=last_return_code, cmd=cmd)
subprocess.CalledProcessError: Command '['/home/dsys2352/miniconda3/envs/dist_GNN/bin/python', '-u', 'GCN_Cora_Distributed_MulNode.py']' returned non-zero exit status 1.
Killing subprocess 289176
srun: error: node024: task 2: Exited with exit code 1
